<?xml version="1.0"?>
<sdf version='1.7'>
    <!--model definition-->
    <!--xacro(https://github.com/ros-industrial/universal_robot) -> urdf(use xacro) -> sdf(use ign sdf -p),and it's modified -->
    <xmacro_define_block name='ur10' params="parent">
        <link name='base_link'>
            <pose relative_to='${parent}'>0 0 0 0 0 0</pose>
            <inertial>
                <mass>4</mass>
                <inertia>
                    <ixx>0.00610633</ixx>
                    <ixy>0</ixy>
                    <ixz>0</ixz>
                    <iyy>0.00610633</iyy>
                    <iyz>0</iyz>
                    <izz>0.01125</izz>
                </inertia>
            </inertial>
            <collision name='base_link_collision'>
                <geometry>
                    <mesh>
                        <uri>model://ur10/meshes/collision/base.stl</uri>
                    </mesh>
                </geometry>
            </collision>
            <visual name='base_link_visual'>
                <geometry>
                    <mesh>
                        <uri>model://ur10/meshes/visual/base.dae</uri>
                    </mesh>
                </geometry>
            </visual>
            <self_collide>1</self_collide>
        </link>
        <joint name='shoulder_pan_joint' type='revolute'>
            <pose relative_to='base_link'>0 0 0.1273 0 -0 0</pose>
            <parent>base_link</parent>
            <child>shoulder_link</child>
            <axis>
                <xyz>0 0 1</xyz>
                <limit>
                    <lower>-6.28319</lower>
                    <upper>6.28319</upper>
                    <effort>330</effort>
                    <velocity>2.16</velocity>
                </limit>
                <dynamics>
                    <damping>0</damping>
                    <friction>0</friction>
                    <spring_reference>0</spring_reference>
                    <spring_stiffness>0</spring_stiffness>
                </dynamics>
            </axis>
        </joint>
        <link name='shoulder_link'>
            <pose relative_to='shoulder_pan_joint'>0 0 0 0 -0 0</pose>
            <inertial>
                <mass>7.778</mass>
                <inertia>
                    <ixx>0.0314743</ixx>
                    <ixy>0</ixy>
                    <ixz>0</ixz>
                    <iyy>0.0314743</iyy>
                    <iyz>0</iyz>
                    <izz>0.0218756</izz>
                </inertia>
            </inertial>
            <collision name='shoulder_link_collision'>
                <geometry>
                    <mesh>
                        <uri>model://ur10/meshes/collision/shoulder.stl</uri>
                    </mesh>
                </geometry>
            </collision>
            <visual name='shoulder_link_visual'>
                <geometry>
                    <mesh>
                        <uri>model://ur10/meshes/visual/shoulder.dae</uri>
                    </mesh>
                </geometry>
            </visual>
            <self_collide>1</self_collide>
        </link>
        <joint name='shoulder_lift_joint' type='revolute'>
            <pose relative_to='shoulder_link'>0 0.220941 0 0 1.5708 0</pose>
            <parent>shoulder_link</parent>
            <child>upper_arm_link</child>
            <axis>
                <xyz>0 1 0</xyz>
                <limit>
                    <lower>-6.28319</lower>
                    <upper>6.28319</upper>
                    <effort>330</effort>
                    <velocity>2.16</velocity>
                </limit>
                <dynamics>
                    <damping>0</damping>
                    <friction>0</friction>
                    <spring_reference>0</spring_reference>
                    <spring_stiffness>0</spring_stiffness>
                </dynamics>
            </axis>
        </joint>
        <link name='upper_arm_link'>
            <pose relative_to='shoulder_lift_joint'>0 0 0 0 -0 0</pose>
            <inertial>
                <pose>0 -0.045 0.306 0 -0 0</pose>
                <mass>12.93</mass>
                <inertia>
                    <ixx>0.421754</ixx>
                    <ixy>0</ixy>
                    <ixz>0</ixz>
                    <iyy>0.421754</iyy>
                    <iyz>0</iyz>
                    <izz>0.0363656</izz>
                </inertia>
            </inertial>
            <collision name='upper_arm_link_collision'>
                <geometry>
                    <mesh>
                        <uri>model://ur10/meshes/collision/upperarm.stl</uri>
                    </mesh>
                </geometry>
            </collision>
            <visual name='upper_arm_link_visual'>
                <geometry>
                    <mesh>
                        <uri>model://ur10/meshes/visual/upperarm.dae</uri>
                    </mesh>
                </geometry>
            </visual>
            <self_collide>1</self_collide>
        </link>
        <joint name='elbow_joint' type='revolute'>
            <pose relative_to='upper_arm_link'>0 -0.1719 0.612 0 -0 0</pose>
            <parent>upper_arm_link</parent>
            <child>forearm_link</child>
            <axis>
                <xyz>0 1 0</xyz>
                <limit>
                    <lower>-3.14159</lower>
                    <upper>3.14159</upper>
                    <effort>150</effort>
                    <velocity>3.15</velocity>
                </limit>
                <dynamics>
                    <damping>0</damping>
                    <friction>0</friction>
                    <spring_reference>0</spring_reference>
                    <spring_stiffness>0</spring_stiffness>
                </dynamics>
            </axis>
        </joint>
        <link name='forearm_link'>
            <pose relative_to='elbow_joint'>0 0 0 0 -0 0</pose>
            <inertial>
                <pose>0 0 0.28615 0 -0 0</pose>
                <mass>3.87</mass>
                <inertia>
                    <ixx>0.11107</ixx>
                    <ixy>0</ixy>
                    <ixz>0</ixz>
                    <iyy>0.11107</iyy>
                    <iyz>0</iyz>
                    <izz>0.0108844</izz>
                </inertia>
            </inertial>
            <collision name='forearm_link_collision'>
                <geometry>
                    <mesh>
                        <uri>model://ur10/meshes/collision/forearm.stl</uri>
                    </mesh>
                </geometry>
            </collision>
            <visual name='forearm_link_visual'>
                <geometry>
                    <mesh>
                        <uri>model://ur10/meshes/visual/forearm.dae</uri>
                    </mesh>
                </geometry>
            </visual>
            <self_collide>1</self_collide>
        </link>
        <joint name='wrist_1_joint' type='revolute'>
            <pose relative_to='forearm_link'>0 0 0.5723 0 1.5708 0</pose>
            <parent>forearm_link</parent>
            <child>wrist_1_link</child>
            <axis>
                <xyz>0 1 0</xyz>
                <limit>
                    <lower>-6.28319</lower>
                    <upper>6.28319</upper>
                    <effort>54</effort>
                    <velocity>3.2</velocity>
                </limit>
                <dynamics>
                    <damping>0</damping>
                    <friction>0</friction>
                    <spring_reference>0</spring_reference>
                    <spring_stiffness>0</spring_stiffness>
                </dynamics>
            </axis>
        </joint>
        <link name='wrist_1_link'>
            <pose relative_to='wrist_1_joint'>0 0 0 0 -0 0</pose>
            <inertial>
                <pose>0 0.1149 0 0 -0 0</pose>
                <mass>1.96</mass>
                <inertia>
                    <ixx>0.00510825</ixx>
                    <ixy>0</ixy>
                    <ixz>0</ixz>
                    <iyy>0.00510825</iyy>
                    <iyz>0</iyz>
                    <izz>0.0055125</izz>
                </inertia>
            </inertial>
            <collision name='wrist_1_link_collision'>
                <geometry>
                    <mesh>
                        <uri>model://ur10/meshes/collision/wrist1.stl</uri>
                    </mesh>
                </geometry>
            </collision>
            <visual name='wrist_1_link_visual'>
                <geometry>
                    <mesh>
                        <uri>model://ur10/meshes/visual/wrist1.dae</uri>
                    </mesh>
                </geometry>
            </visual>
            <self_collide>1</self_collide>
        </link>
        <joint name='wrist_2_joint' type='revolute'>
            <pose relative_to='wrist_1_link'>0 0.1149 0 0 -0 0</pose>
            <parent>wrist_1_link</parent>
            <child>wrist_2_link</child>
            <axis>
                <xyz>0 0 1</xyz>
                <limit>
                    <lower>-6.28319</lower>
                    <upper>6.28319</upper>
                    <effort>54</effort>
                    <velocity>3.2</velocity>
                </limit>
                <dynamics>
                    <damping>0</damping>
                    <friction>0</friction>
                    <spring_reference>0</spring_reference>
                    <spring_stiffness>0</spring_stiffness>
                </dynamics>
            </axis>
        </joint>
        <link name='wrist_2_link'>
            <pose relative_to='wrist_2_joint'>0 0 0 0 -0 0</pose>
            <inertial>
                <pose>0 0 0.1157 0 -0 0</pose>
                <mass>1.96</mass>
                <inertia>
                    <ixx>0.00510825</ixx>
                    <ixy>0</ixy>
                    <ixz>0</ixz>
                    <iyy>0.00510825</iyy>
                    <iyz>0</iyz>
                    <izz>0.0055125</izz>
                </inertia>
            </inertial>
            <collision name='wrist_2_link_collision'>
                <geometry>
                    <mesh>
                        <uri>model://ur10/meshes/collision/wrist2.stl</uri>
                    </mesh>
                </geometry>
            </collision>
            <visual name='wrist_2_link_visual'>
                <geometry>
                    <mesh>
                        <uri>model://ur10/meshes/visual/wrist2.dae</uri>
                    </mesh>
                </geometry>
            </visual>
            <self_collide>1</self_collide>
        </link>
        <joint name='wrist_3_joint' type='revolute'>
            <pose relative_to='wrist_2_link'>0 0 0.1157 0 -0 0</pose>
            <parent>wrist_2_link</parent>
            <child>wrist_3_link</child>
            <axis>
                <xyz>0 1 0</xyz>
                <limit>
                    <lower>-6.28319</lower>
                    <upper>6.28319</upper>
                    <effort>54</effort>
                    <velocity>3.2</velocity>
                </limit>
                <dynamics>
                    <damping>0</damping>
                    <friction>0</friction>
                    <spring_reference>0</spring_reference>
                    <spring_stiffness>0</spring_stiffness>
                </dynamics>
            </axis>
        </joint>
        <link name='wrist_3_link'>
            <pose relative_to='wrist_3_joint'>0 0 0 0 -0 0</pose>
            <inertial>
                <pose>0 0.07695 0 1.5708 -0 0</pose>
                <mass>0.202</mass>
                <inertia>
                    <ixx>0.000117922</ixx>
                    <ixy>0</ixy>
                    <ixz>0</ixz>
                    <iyy>0.000117922</iyy>
                    <iyz>0</iyz>
                    <izz>0.000204525</izz>
                </inertia>
            </inertial>
            <collision name='wrist_3_link_collision'>
                <geometry>
                    <mesh>
                        <uri>model://ur10/meshes/collision/wrist3.stl</uri>
                    </mesh>
                </geometry>
            </collision>
            <visual name='wrist_3_link_visual'>
                <geometry>
                    <mesh>
                        <uri>model://ur10/meshes/visual/wrist3.dae</uri>
                    </mesh>
                </geometry>
            </visual>
            <self_collide>1</self_collide>
        </link>
        <joint name="ee_fixed_joint" type="fixed">
        	<pose relative_to="wrist_3_link">0.0 0.0922 0.0 0.0 0.0 1.5707963267948966</pose>
            <parent>wrist_3_link</parent>
            <child>ee_link</child>
        </joint>
        <link name='ee_link'>
            <inertial>
                <xmacro_block name="inertia_box" m="0.001" x="0.01" y="0.01" z="0.01" />
            </inertial>
            <collision name="collision">
                <xmacro_block name="geometry_box" x="0.01" y="0.01" z="0.01" />
            </collision>
            <self_collide>1</self_collide>
        </link>
    </xmacro_define_block>
    <!--controller definition-->
    <xmacro_define_block name='ur10_position_controller'>
        <plugin filename="ignition-gazebo-joint-position-controller-system" name="ignition::gazebo::systems::JointPositionController">
            <joint_name>shoulder_pan_joint</joint_name>
            <p_gain>10000</p_gain>
            <i_gain>100</i_gain>
            <d_gain>500</d_gain>
            <i_max>200.0</i_max>
            <i_min>-200.0</i_min>
        </plugin>
        <plugin filename="ignition-gazebo-joint-position-controller-system" name="ignition::gazebo::systems::JointPositionController">
            <joint_name>shoulder_lift_joint</joint_name>
            <p_gain>50000</p_gain>
            <i_gain>100</i_gain>
            <d_gain>1000</d_gain>
            <i_max>200.0</i_max>
            <i_min>-200.0</i_min>
        </plugin>
        <plugin filename="ignition-gazebo-joint-position-controller-system" name="ignition::gazebo::systems::JointPositionController">
            <joint_name>elbow_joint</joint_name>
            <p_gain>50000.0</p_gain>
            <i_gain>100</i_gain>
            <d_gain>1000</d_gain>
            <i_max>200</i_max>
            <i_min>-200</i_min>
        </plugin>
        <plugin filename="ignition-gazebo-joint-position-controller-system" name="ignition::gazebo::systems::JointPositionController">
            <joint_name>wrist_1_joint</joint_name>
            <p_gain>100.0</p_gain>
            <i_gain>50.0</i_gain>
            <d_gain>10.0</d_gain>
            <i_max>10.0</i_max>
            <i_min>-10.0</i_min>
        </plugin>
        <plugin filename="ignition-gazebo-joint-position-controller-system" name="ignition::gazebo::systems::JointPositionController">
            <joint_name>wrist_2_joint</joint_name>
            <p_gain>75.0</p_gain>
            <i_gain>10</i_gain>
            <d_gain>5</d_gain>
            <i_max>10.0</i_max>
            <i_min>-10.0</i_min>
        </plugin>
        <plugin filename="ignition-gazebo-joint-position-controller-system" name="ignition::gazebo::systems::JointPositionController">
            <joint_name>wrist_3_joint</joint_name>
            <p_gain>25.0</p_gain>
            <i_gain>10</i_gain>
            <d_gain>0.1</d_gain>
            <i_max>10.0</i_max>
            <i_min>-10.0</i_min>
        </plugin>
    </xmacro_define_block>
</sdf>