<?xml version="1.0"?>
<sdf version='1.7'>
    <!--model definition-->
    <!--xacro(https://github.com/ros-industrial/universal_robot) -> urdf(use xacro) -> sdf(use ign sdf -p),and it's modified -->
    <xmacro_define_block name='ur5' params="parent">
        <link name='base_link'>
            <pose relative_to='${parent}'>0 0 0 0 0 0</pose>
            <inertial>
                <mass>4</mass>
                <inertia>
                    <ixx>0.00443333</ixx>
                    <ixy>0</ixy>
                    <ixz>0</ixz>
                    <iyy>0.00443333</iyy>
                    <iyz>0</iyz>
                    <izz>0.0072</izz>
                </inertia>
            </inertial>
            <collision name='base_link_collision'>
                <geometry>
                    <mesh>
                        <uri>model://ur5/meshes/collision/base.stl</uri>
                    </mesh>
                </geometry>
            </collision>
            <visual name='base_link_visual'>
                <geometry>
                    <mesh>
                        <uri>model://ur5/meshes/visual/base.dae</uri>
                    </mesh>
                </geometry>
            </visual>
        </link>
        <joint name='shoulder_pan_joint' type='revolute'>
            <pose relative_to='base_link'>0 0 0.089159 0 -0 0</pose>
            <parent>base_link</parent>
            <child>shoulder_link</child>
            <axis>
                <xyz>0 0 1</xyz>
                <limit>
                    <lower>-6.28319</lower>
                    <upper>6.28319</upper>
                    <effort>150</effort>
                    <velocity>3.15</velocity>
                </limit>
                <dynamics>
                    <damping>0</damping>
                    <friction>0</friction>
                    <spring_reference>0</spring_reference>
                    <spring_stiffness>0</spring_stiffness>
                </dynamics>
            </axis>
        </joint>
        <link name='shoulder_link'>
            <pose relative_to='shoulder_pan_joint'>0 0 0 0 -0 0</pose>
            <inertial>
                <mass>3.7</mass>
                <inertia>
                    <ixx>0.0102675</ixx>
                    <ixy>0</ixy>
                    <ixz>0</ixz>
                    <iyy>0.0102675</iyy>
                    <iyz>0</iyz>
                    <izz>0.00666</izz>
                </inertia>
            </inertial>
            <collision name='shoulder_link_collision'>
                <geometry>
                    <mesh>
                        <uri>model://ur5/meshes/collision/shoulder.stl</uri>
                    </mesh>
                </geometry>
            </collision>
            <visual name='shoulder_link_visual'>
                <geometry>
                    <mesh>
                        <uri>model://ur5/meshes/visual/shoulder.dae</uri>
                    </mesh>
                </geometry>
            </visual>
            <self_collide>1</self_collide>
        </link>
        <joint name='shoulder_lift_joint' type='revolute'>
            <pose relative_to='shoulder_link'>0 0.13585 0 0 1.5708 0</pose>
            <parent>shoulder_link</parent>
            <child>upper_arm_link</child>
            <axis>
                <xyz>0 1 0</xyz>
                <limit>
                    <lower>-6.28319</lower>
                    <upper>6.28319</upper>
                    <effort>150</effort>
                    <velocity>3.15</velocity>
                </limit>
                <dynamics>
                    <damping>0</damping>
                    <friction>0</friction>
                    <spring_reference>0</spring_reference>
                    <spring_stiffness>0</spring_stiffness>
                </dynamics>
            </axis>
        </joint>
        <link name='upper_arm_link'>
            <pose relative_to='shoulder_lift_joint'>0 0 0 0 -0 0</pose>
            <inertial>
                <pose>0 0 0.28 0 -0 0</pose>
                <mass>8.393</mass>
                <inertia>
                    <ixx>0.226891</ixx>
                    <ixy>0</ixy>
                    <ixz>0</ixz>
                    <iyy>0.226891</iyy>
                    <iyz>0</iyz>
                    <izz>0.0151074</izz>
                </inertia>
            </inertial>
            <collision name='upper_arm_link_collision'>
                <geometry>
                    <mesh>
                        <uri>model://ur5/meshes/collision/upperarm.stl</uri>
                    </mesh>
                </geometry>
            </collision>
            <visual name='upper_arm_link_visual'>
                <geometry>
                    <mesh>
                        <uri>model://ur5/meshes/visual/upperarm.dae</uri>
                    </mesh>
                </geometry>
            </visual>
            <self_collide>1</self_collide>
        </link>
        <joint name='elbow_joint' type='revolute'>
            <pose relative_to='upper_arm_link'>0 -0.1197 0.425 0 -0 0</pose>
            <parent>upper_arm_link</parent>
            <child>forearm_link</child>
            <axis>
                <xyz>0 1 0</xyz>
                <limit>
                    <lower>-3.14159</lower>
                    <upper>3.14159</upper>
                    <effort>150</effort>
                    <velocity>3.15</velocity>
                </limit>
                <dynamics>
                    <damping>0</damping>
                    <friction>0</friction>
                    <spring_reference>0</spring_reference>
                    <spring_stiffness>0</spring_stiffness>
                </dynamics>
            </axis>
        </joint>
        <link name='forearm_link'>
            <pose relative_to='elbow_joint'>0 0 0 0 -0 0</pose>
            <inertial>
                <pose>0 0 0.196125 0 -0 0</pose>
                <mass>2.275</mass>
                <inertia>
                    <ixx>0.0312168</ixx>
                    <ixy>0</ixy>
                    <ixz>0</ixz>
                    <iyy>0.0312168</iyy>
                    <iyz>0</iyz>
                    <izz>0.004095</izz>
                </inertia>
            </inertial>
            <collision name='forearm_link_collision'>
                <geometry>
                    <mesh>
                        <uri>model://ur5/meshes/collision/forearm.stl</uri>
                    </mesh>
                </geometry>
            </collision>
            <visual name='forearm_link_visual'>
                <geometry>
                    <mesh>
                        <uri>model://ur5/meshes/visual/forearm.dae</uri>
                    </mesh>
                </geometry>
            </visual>
            <self_collide>1</self_collide>
        </link>
        <joint name='wrist_1_joint' type='revolute'>
            <pose relative_to='forearm_link'>0 0 0.39225 0 1.5708 0</pose>
            <parent>forearm_link</parent>
            <child>wrist_1_link</child>
            <axis>
                <xyz>0 1 0</xyz>
                <limit>
                    <lower>-6.28319</lower>
                    <upper>6.28319</upper>
                    <effort>28</effort>
                    <velocity>3.2</velocity>
                </limit>
                <dynamics>
                    <damping>0</damping>
                    <friction>0</friction>
                    <spring_reference>0</spring_reference>
                    <spring_stiffness>0</spring_stiffness>
                </dynamics>
            </axis>
        </joint>
        <link name='wrist_1_link'>
            <pose relative_to='wrist_1_joint'>0 0 0 0 -0 0</pose>
            <inertial>
                <pose>0 0.093 0 0 -0 0</pose>
                <mass>1.219</mass>
                <inertia>
                    <ixx>0.0025599</ixx>
                    <ixy>0</ixy>
                    <ixz>0</ixz>
                    <iyy>0.0025599</iyy>
                    <iyz>0</iyz>
                    <izz>0.0021942</izz>
                </inertia>
            </inertial>
            <collision name='wrist_1_link_collision'>
                <geometry>
                    <mesh>
                        <uri>model://ur5/meshes/collision/wrist1.stl</uri>
                    </mesh>
                </geometry>
            </collision>
            <visual name='wrist_1_link_visual'>
                <geometry>
                    <mesh>
                        <uri>model://ur5/meshes/visual/wrist1.dae</uri>
                    </mesh>
                </geometry>
            </visual>
            <self_collide>1</self_collide>
        </link>
        <joint name='wrist_2_joint' type='revolute'>
            <pose relative_to='wrist_1_link'>0 0.093 0 0 -0 0</pose>
            <parent>wrist_1_link</parent>
            <child>wrist_2_link</child>
            <axis>
                <xyz>0 0 1</xyz>
                <limit>
                    <lower>-6.28319</lower>
                    <upper>6.28319</upper>
                    <effort>28</effort>
                    <velocity>3.2</velocity>
                </limit>
                <dynamics>
                    <damping>0</damping>
                    <friction>0</friction>
                    <spring_reference>0</spring_reference>
                    <spring_stiffness>0</spring_stiffness>
                </dynamics>
            </axis>
        </joint>
        <link name='wrist_2_link'>
            <pose relative_to='wrist_2_joint'>0 0 0 0 -0 0</pose>
            <inertial>
                <pose>0 0 0.09465 0 -0 0</pose>
                <mass>1.219</mass>
                <inertia>
                    <ixx>0.0025599</ixx>
                    <ixy>0</ixy>
                    <ixz>0</ixz>
                    <iyy>0.0025599</iyy>
                    <iyz>0</iyz>
                    <izz>0.0021942</izz>
                </inertia>
            </inertial>
            <collision name='wrist_2_link_collision'>
                <geometry>
                    <mesh>
                        <uri>model://ur5/meshes/collision/wrist2.stl</uri>
                    </mesh>
                </geometry>
            </collision>
            <visual name='wrist_2_link_visual'>
                <geometry>
                    <mesh>
                        <uri>model://ur5/meshes/visual/wrist2.dae</uri>
                    </mesh>
                </geometry>
            </visual>
            <self_collide>1</self_collide>
        </link>
        <joint name='wrist_3_joint' type='revolute'>
            <pose relative_to='wrist_2_link'>0 0 0.09465 0 -0 0</pose>
            <parent>wrist_2_link</parent>
            <child>wrist_3_link</child>
            <axis>
                <xyz>0 1 0</xyz>
                <limit>
                    <lower>-6.28319</lower>
                    <upper>6.28319</upper>
                    <effort>28</effort>
                    <velocity>3.2</velocity>
                </limit>
                <dynamics>
                    <damping>0</damping>
                    <friction>0</friction>
                    <spring_reference>0</spring_reference>
                    <spring_stiffness>0</spring_stiffness>
                </dynamics>
            </axis>
        </joint>
        <link name='wrist_3_link'>
            <pose relative_to='wrist_3_joint'>0 0 0 0 -0 0</pose>
            <inertial>
                <pose>0 0.06505 0 1.5708 -0 0</pose>
                <mass>0.1879</mass>
                <inertia>
                    <ixx>8.46959e-05</ixx>
                    <ixy>0</ixy>
                    <ixz>0</ixz>
                    <iyy>8.46959e-05</iyy>
                    <iyz>0</iyz>
                    <izz>0.000132117</izz>
                </inertia>
            </inertial>
            <collision name='wrist_3_link_collision'>
                <geometry>
                    <mesh>
                        <uri>model://ur5/meshes/collision/wrist3.stl</uri>
                    </mesh>
                </geometry>
            </collision>
            <visual name='wrist_3_link_visual'>
                <geometry>
                    <mesh>
                        <uri>model://ur5/meshes/visual/wrist3.dae</uri>
                    </mesh>
                </geometry>
            </visual>
            <self_collide>1</self_collide>
        </link>
    </xmacro_define_block>
</sdf>